Workbook

Sheet DMS data
A1: Dataset_Num | B1: Dataset_ID | C1: DS_comment | D1: DS_instrument_name_ID | E1: DS_storage_path_ID | F1: DS_rating | G1: Acq_Time_Start | H1: Acq_Time_End | I1: Acq_Length_Minutes | J1: IN_name | K1: StoragePath | L1: shortname | M1: bsm Idfrom Sujay's GOLD json | N1: NCBI IDs linked to dataset name | O1: NCBI IDs linked to sample short name | P1: GOLD bioproject | Q1: nmdc biosample id | R1: anc comments
A2: EMP_Feces_song_51_s005_a03_M_133 | B2: 698859 | D2: 94 | E2: 2856 | F2: 5 | G2: 43357.989 | H2: 43358.015 | I2: 37 | J2: Agilent_GC_MS_02 | K2: \\proto-4\Agilent_GC_MS_02\2018_3\EMP_Feces_song_51_s005_a03_M_133\ | L2: =IF(LEFT(A2,10)="EMP_Feces_",MID(A2,11,FIND("a0",A2,1)-12),"None") -> song_51_s005 | M2: =IF(NOT(L2="None"),VLOOKUP(L2,'GOLD Name splitout'!$A$1:$B$458,2,FALSE),"None") -> nmdc:bsm-11-040pda34 | N2: =VLOOKUP(A2,DMSNameNCBIIDXNLExtract!$A$2:$B$318,2,FALSE) -> SAMEA7723514 | O2: =VLOOKUP(L2,DMSNameNCBIIDXNLExtract!$E$2:$G$1025,2,FALSE) -> SAMEA7723514 | P2: =VLOOKUP(O2,'anc gold to biosample'!$A$2:$B$1025,2,FALSE) -> Gb0315872 | Q2: =VLOOKUP(P2,'anc nmdc ncbi gold'!$A$2:$C$818,2,FALSE) -> nmdc:bsm-11-040pda34 | R2: some nmdc biosample ids subject to change, update 'anc nmdc ncbi gold' before using for prod work
A3: EMP_Feces_bittleston_68_s014_a02_M_356 | B3: 700401 | D3: 94 | E3: 2856 | F3: 5 | G3: 43369.119 | H3: 43369.145 | I3: 37 | J3: Agilent_GC_MS_02 | K3: \\proto-4\Agilent_GC_MS_02\2018_3\EMP_Feces_bittleston_68_s014_a02_M_356\ | L3: =IF(LEFT(A3,10)="EMP_Feces_",MID(A3,11,FIND("a0",A3,1)-12),"None") -> bittleston_68_s014 | M3: =IF(NOT(L3="None"),VLOOKUP(L3,'GOLD Name splitout'!$A$1:$B$458,2,FALSE),"None") -> nmdc:bsm-11-04z8tj85 | N3: =VLOOKUP(A3,DMSNameNCBIIDXNLExtract!$A$2:$B$318,2,FALSE) -> #N/A | O3: =VLOOKUP(L3,DMSNameNCBIIDXNLExtract!$E$2:$G$1025,2,FALSE) -> SAMEA7723870 | P3: =VLOOKUP(O3,'anc gold to biosample'!$A$2:$B$1025,2,FALSE) -> Gb0315739 | Q3: =VLOOKUP(P3,'anc nmdc ncbi gold'!$A$2:$C$818,2,FALSE) -> nmdc:bsm-11-04z8tj85 | R3: some nmdc biosample ids subject to change, update 'anc nmdc ncbi gold' before using for prod work
A4: EMP_Sdf_JP1_18_071_GC | B4: 700691 | C4: ; Auto-switched invalid dataset type from GC to default: GC-MS | D4: 94 | E4: 2856 | F4: 5 | G4: 43370.653 | H4: 43370.679 | I4: 37 | J4: Agilent_GC_MS_02 | K4: \\proto-4\Agilent_GC_MS_02\2018_3\EMP_Sdf_JP1_18_071_GC\ | L4: =IF(LEFT(A4,10)="EMP_Feces_",MID(A4,11,FIND("a0",A4,1)-12),"None") -> None | M4: =IF(NOT(L4="None"),VLOOKUP(L4,'GOLD Name splitout'!$A$1:$B$458,2,FALSE),"None") -> None | N4: =VLOOKUP(A4,DMSNameNCBIIDXNLExtract!$A$2:$B$318,2,FALSE) -> SAMEA7724288 | O4: =N4 -> SAMEA7724288 | P4: =VLOOKUP(O4,'anc gold to biosample'!$A$2:$B$1025,2,FALSE) -> Gb0239938 | Q4: =VLOOKUP(P4,'anc nmdc ncbi gold'!$A$2:$C$818,2,FALSE) -> nmdc:bsm-11-06pa9m89 | R4: some nmdc biosample ids subject to change, update 'anc nmdc ncbi gold' before using for prod work
A5: EMP_Feces_king_27_s018_a03_M_222 | B5: 699486 | D5: 94 | E5: 2856 | F5: 5 | G5: 43362.907 | H5: 43362.933 | I5: 37 | J5: Agilent_GC_MS_02 | K5: \\proto-4\Agilent_GC_MS_02\2018_3\EMP_Feces_king_27_s018_a03_M_222\ | L5: =IF(LEFT(A5,10)="EMP_Feces_",MID(A5,11,FIND("a0",A5,1)-12),"None") -> king_27_s018 | M5: =IF(NOT(L5="None"),VLOOKUP(L5,'GOLD Name splitout'!$A$1:$B$458,2,FALSE),"None") -> #N/A | N5: =VLOOKUP(A5,DMSNameNCBIIDXNLExtract!$A$2:$B$318,2,FALSE) -> SAMEA7723435 | O5: =VLOOKUP(L5,DMSNameNCBIIDXNLExtract!$E$2:$G$1025,2,FALSE) -> SAMEA7723435 | P5: =VLOOKUP(O5,'anc gold to biosample'!$A$2:$B$1025,2,FALSE) -> Gb0240128 | Q5: =VLOOKUP(P5,'anc nmdc ncbi gold'!$A$2:$C$818,2,FALSE) -> nmdc:bsm-11-08fpzx54 | R5: some nmdc biosample ids subject to change, update 'anc nmdc ncbi gold' before using for prod work
A6: EMP_Feces_mayer_34_s002_a03_M_081 | B6: 698509 | D6: 94 | E6: 2856 | F6: 5 | G6: 43356.215 | H6: 43356.241 | I6: 37 | J6: Agilent_GC_MS_02 | K6: \\proto-4\Agilent_GC_MS_02\2018_3\EMP_Feces_mayer_34_s002_a03_M_081\ | L6: =IF(LEFT(A6,10)="EMP_Feces_",MID(A6,11,FIND("a0",A6,1)-12),"None") -> mayer_34_s002 | M6: =IF(NOT(L6="None"),VLOOKUP(L6,'GOLD Name splitout'!$A$1:$B$458,2,FALSE),"None") -> nmdc:bsm-11-097t3b49 | N6: =VLOOKUP(A6,DMSNameNCBIIDXNLExtract!$A$2:$B$318,2,FALSE) -> SAMEA7723441 | O6: =VLOOKUP(L6,DMSNameNCBIIDXNLExtract!$E$2:$G$1025,2,FALSE) -> SAMEA7723441 | P6: =VLOOKUP(O6,'anc gold to biosample'!$A$2:$B$1025,2,FALSE) -> Gb0315756 | Q6: =VLOOKUP(P6,'anc nmdc ncbi gold'!$A$2:$C$818,2,FALSE) -> nmdc:bsm-11-097t3b49 | R6: some nmdc biosample ids subject to change, update 'anc nmdc ncbi gold' before using for prod work
A7: EMP_Feces_girguis_50_s007_a03_M_123 | B7: 698820 | D7: 94 | E7: 2856 | F7: 5 | G7: 43357.575 | H7: 43357.601 | I7: 37 | J7: Agilent_GC_MS_02 | K7: \\proto-4\Agilent_GC_MS_02\2018_3\EMP_Feces_girguis_50_s007_a03_M_123\ | L7: =IF(LEFT(A7,10)="EMP_Feces_",MID(A7,11,FIND("a0",A7,1)-12),"None") -> girguis_50_s007 | M7: =IF(NOT(L7="None"),VLOOKUP(L7,'GOLD Name splitout'!$A$1:$B$458,2,FALSE),"None") -> nmdc:bsm-11-0g4d7n95 | N7: =VLOOKUP(A7,DMSNameNCBIIDXNLExtract!$A$2:$B$318,2,FALSE) -> SAMEA7723413 | O7: =VLOOKUP(L7,DMSNameNCBIIDXNLExtract!$E$2:$G$1025,2,FALSE) -> SAMEA7723413 | P7: =VLOOKUP(O7,'anc gold to biosample'!$A$2:$B$1025,2,FALSE) -> Gb0315861 | Q7: =VLOOKUP(P7,'anc nmdc ncbi gold'!$A$2:$C$818,2,FALSE) -> nmdc:bsm-11-0g4d7n95 | R7: some nmdc biosample ids subject to change, update 'anc nmdc ncbi gold' before using for prod work
A8: EMP_Feces_song_53_s009_a03_M_172 | B8: 699186 | D8: 94 | E8: 2856 | F8: 5 | G8: 43361.193 | H8: 43361.219 | I8: 37 | J8: Agilent_GC_MS_02 | K8: \\proto-4\Agilent_GC_MS_02\2018_3\EMP_Feces_song_53_s009_a03_M_172\ | L8: =IF(LEFT(A8,10)="EMP_Feces_",MID(A8,11,FIND("a0",A8,1)-12),"None") -> song_53_s009 | M8: =IF(NOT(L8="None"),VLOOKUP(L8,'GOLD Name splitout'!$A$1:$B$458,2,FALSE),"None") -> nmdc:bsm-11-0q0ytn25 | N8: =VLOOKUP(A8,DMSNameNCBIIDXNLExtract!$A$2:$B$318,2,FALSE) -> SAMEA7723534 | O8: =VLOOKUP(L8,DMSNameNCBIIDXNLExtract!$E$2:$G$1025,2,FALSE) -> SAMEA7723534 | P8: =VLOOKUP(O8,'anc gold to biosample'!$A$2:$B$1025,2,FALSE) -> Gb0315892 | Q8: =VLOOKUP(P8,'anc nmdc ncbi gold'!$A$2:$C$818,2,FALSE) -> nmdc:bsm-11-0q0ytn25 | R8: some nmdc biosample ids subject to change, update 'anc nmdc ncbi gold' before using for prod work
A9: EMP_Feces_mousseau_88_s001_a02_M_285 | B9: 699741 | D9: 94 | E9: 2856 | F9: 5 | G9: 43365.007 | H9: 43365.033 | I9: 37 | J9: Agilent_GC_MS_02 | K9: \\proto-4\Agilent_GC_MS_02\2018_3\EMP_Feces_mousseau_88_s001_a02_M_285\ | L9: =IF(LEFT(A9,10)="EMP_Feces_",MID(A9,11,FIND("a0",A9,1)-12),"None") -> mousseau_88_s001 | M9: =IF(NOT(L9="None"),VLOOKUP(L9,'GOLD Name splitout'!$A$1:$B$458,2,FALSE),"None") -> nmdc:bsm-11-0t4hha86 | N9: =VLOOKUP(A9,DMSNameNCBIIDXNLExtract!$A$2:$B$318,2,FALSE) -> SAMEA7723617 | O9: =VLOOKUP(L9,DMSNameNCBIIDXNLExtract!$E$2:$G$1025,2,FALSE) -> SAMEA7723617 | P9: =VLOOKUP(O9,'anc gold to biosample'!$A$2:$B$1025,2,FALSE) -> Gb0315898 | Q9: =VLOOKUP(P9,'anc nmdc ncbi gold'!$A$2:$C$818,2,FALSE) -> nmdc:bsm-11-0t4hha86 | R9: some nmdc biosample ids subject to change, update 'anc nmdc ncbi gold' before using for prod work
A10: EMP_Feces_pinto_63_s003_a03_M_330 | B10: 700337 | D10: 94 | E10: 2856 | F10: 5 | G10: 43368.263 | H10: 43368.289 | I10: 37 | J10: Agilent_GC_MS_02 | K10: \\proto-4\Agilent_GC_MS_02\2018_3\EMP_Feces_pinto_63_s003_a03_M_330\ | L10: =IF(LEFT(A10,10)="EMP_Feces_",MID(A10,11,FIND("a0",A10,1)-12),"None") -> pinto_63_s003 | M10: =IF(NOT(L10="None"),VLOOKUP(L10,'GOLD Name splitout'!$A$1:$B$458,2,FALSE),"None") -> nmdc:bsm-11-0ve03274 | N10: =VLOOKUP(A10,DMSNameNCBIIDXNLExtract!$A$2:$B$318,2,FALSE) -> SAMEA7723461 | O10: =VLOOKUP(L10,DMSNameNCBIIDXNLExtract!$E$2:$G$1025,2,FALSE) -> SAMEA7723461 | P10: =VLOOKUP(O10,'anc gold to biosample'!$A$2:$B$1025,2,FALSE) -> Gb0315669 | Q10: =VLOOKUP(P10,'anc nmdc ncbi gold'!$A$2:$C$818,2,FALSE) -> nmdc:bsm-11-0ve03274 | R10: some nmdc biosample ids subject to change, update 'anc nmdc ncbi gold' before using for prod work
A11: EMP_Feces_berry_2_s012_a03_M_095 | B11: 698751 | D11: 94 | E11: 2856 | F11: 5 | G11: 43356.747 | H11: 43356.773 | I11: 37 | J11: Agilent_GC_MS_02 | K11: \\proto-4\Agilent_GC_MS_02\2018_3\EMP_Feces_berry_2_s012_a03_M_095\ | L11: =IF(LEFT(A11,10)="EMP_Feces_",MID(A11,11,FIND("a0",A11,1)-12),"None") -> berry_2_s012 | M11: =IF(NOT(L11="None"),VLOOKUP(L11,'GOLD Name splitout'!$A$1:$B$458,2,FALSE),"None") -> nmdc:bsm-11-1026rp71 | N11: =VLOOKUP(A11,DMSNameNCBIIDXNLExtract!$A$2:$B$318,2,FALSE) -> #N/A | O11: =VLOOKUP(L11,DMSNameNCBIIDXNLExtract!$E$2:$G$1025,2,FALSE) -> SAMEA7723853 | P11: =VLOOKUP(O11,'anc gold to biosample'!$A$2:$B$1025,2,FALSE) -> Gb0315770 | Q11: =VLOOKUP(P11,'anc nmdc ncbi gold'!$A$2:$C$818,2,FALSE) -> nmdc:bsm-11-1026rp71 | R11: some nmdc biosample ids subject to change, update 'anc nmdc ncbi gold' before using for prod work
A12: EMP_McR3_5_007_GC | B12: 698245 | C12: ; Auto-switched invalid dataset type from GC to default: GC-MS | D12: 94 | E12: 2856 | F12: 5 | G12: 43353.816 | H12: 43353.842 | I12: 37 | J12: Agilent_GC_MS_02 | K12: \\proto-4\Agilent_GC_MS_02\2018_3\EMP_McR3_5_007_GC\ | L12: McR3_5 | M12: =IF(NOT(L12="None"),VLOOKUP(L12,'GOLD Name splitout'!$A$1:$B$458,2,FALSE),"None") -> nmdc:bsm-11-1109f777 | N12: =VLOOKUP(A12,DMSNameNCBIIDXNLExtract!$A$2:$B$318,2,FALSE) -> SAMEA7724111 | O12: =VLOOKUP(L12,DMSNameNCBIIDXNLExtract!$E$2:$G$1025,2,FALSE) -> SAMEA7724111 | P12: =VLOOKUP(O12,'anc gold to biosample'!$A$2:$B$1025,2,FALSE) -> Gb0239957 | Q12: =VLOOKUP(P12,'anc nmdc ncbi gold'!$A$2:$C$818,2,FALSE) -> nmdc:bsm-11-1109f777 | R12: some nmdc biosample ids subject to change, update 'anc nmdc ncbi gold' before using for prod work
A13: EMP_Myr_11_NRCS0221_033_GC | B13: 700436 | C13: ; Auto-switched invalid dataset type from GC to default: GC-MS | D13: 94 | E13: 2856 | F13: 5 | G13: 43369.385 | H13: 43369.411 | I13: 37 | J13: Agilent_GC_MS_02 | K13: \\proto-4\Agilent_GC_MS_02\2018_3\EMP_Myr_11_NRCS0221_033_GC\ | L13: =MID(A13,5,15) -> Myr_11_NRCS0221 | M13: =IF(NOT(L13="None"),VLOOKUP(L13,'GOLD Name splitout'!$A$1:$B$458,2,FALSE),"None") -> #N/A | N13: =VLOOKUP(A13,DMSNameNCBIIDXNLExtract!$A$2:$B$318,2,FALSE) -> SAMEA7724217 | O13: =N13 -> SAMEA7724217 | P13: =VLOOKUP(O13,'anc gold to biosample'!$A$2:$B$1025,2,FALSE) -> Gb0240094 | Q13: =VLOOKUP(P13,'anc nmdc ncbi gold'!$A$2:$C$818,2,FALSE) -> nmdc:bsm-11-1302r041 | R13: some nmdc biosample ids subject to change, update 'anc nmdc ncbi gold' before using for prod work
A14: EMP_Feces_rohwer_84_s005_a03_M_270 | B14: 699694 | D14: 94 | E14: 2856 | F14: 5 | G14: 43364.445 | H14: 43364.471 | I14: 37 | J14: Agilent_GC_MS_02 | K14: \\proto-4\Agilent_GC_MS_02\2018_3\EMP_Feces_rohwer_84_s005_a03_M_270\ | L14: =IF(LEFT(A14,10)="EMP_Feces_",MID(A14,11,FIND("a0",A14,1)-12),"None") -> rohwer_84_s005 | M14: =IF(NOT(L14="None"),VLOOKUP(L14,'GOLD Name splitout'!$A$1:$B$458,2,FALSE),"None") -> #N/A | N14: =VLOOKUP(A14,DMSNameNCBIIDXNLExtract!$A$2:$B$318,2,FALSE) -> #N/A | O14: =VLOOKUP(L14,DMSNameNCBIIDXNLExtract!$E$2:$G$1025,2,FALSE) -> SAMEA7723948 | P14: =VLOOKUP(O14,'anc gold to biosample'!$A$2:$B$1025,2,FALSE) -> Gb0239931 | Q14: =VLOOKUP(P14,'anc nmdc ncbi gold'!$A$2:$C$818,2,FALSE) -> nmdc:bsm-11-197ez411 | R14: some nmdc biosample ids subject to change, update 'anc nmdc ncbi gold' before using for prod work
A15: EMP_Feces_minich_76_s006_a03_M_266 | B15: 699688 | D15: 94 | E15: 2856 | F15: 5 | G15: 43364.326 | H15: 43364.352 | I15: 37 | J15: Agilent_GC_MS_02 | K15: \\proto-4\Agilent_GC_MS_02\2018_3\EMP_Feces_minich_76_s006_a03_M_266\ | L15: =IF(LEFT(A15,10)="EMP_Feces_",MID(A15,11,FIND("a0",A15,1)-12),"None") -> minich_76_s006 | M15: =IF(NOT(L15="None"),VLOOKUP(L15,'GOLD Name splitout'!$A$1:$B$458,2,FALSE),"None") -> nmdc:bsm-11-1b0wkq73 | N15: =VLOOKUP(A15,DMSNameNCBIIDXNLExtract!$A$2:$B$318,2,FALSE) -> #N/A | O15: =VLOOKUP(L15,DMSNameNCBIIDXNLExtract!$E$2:$G$1025,2,FALSE) -> SAMEA7723928 | P15: =VLOOKUP(O15,'anc gold to biosample'!$A$2:$B$1025,2,FALSE) -> Gb0315959 | Q15: =VLOOKUP(P15,'anc nmdc ncbi gold'!$A$2:$C$818,2,FALSE) -> nmdc:bsm-11-1b0wkq73 | R15: some nmdc biosample ids subject to change, update 'anc nmdc ncbi gold' before using for prod work
A16: EMP_Feces_song_52_s010_a03_M_158 | B16: 699161 | D16: 94 | E16: 2856 | F16: 5 | G16: 43360.779 | H16: 43360.805 | I16: 37 | J16: Agilent_GC_MS_02 | K16: \\proto-4\Agilent_GC_MS_02\2018_3\EMP_Feces_song_52_s010_a03_M_158\ | L16: =IF(LEFT(A16,10)="EMP_Feces_",MID(A16,11,FIND("a0",A16,1)-12),"None") -> song_52_s010 | M16: =IF(NOT(L16="None"),VLOOKUP(L16,'GOLD Name splitout'!$A$1:$B$458,2,FALSE),"None") -> nmdc:bsm-11-1j6kvc24 | N16: =VLOOKUP(A16,DMSNameNCBIIDXNLExtract!$A$2:$B$318,2,FALSE) -> SAMEA7723524 | O16: =VLOOKUP(L16,DMSNameNCBIIDXNLExtract!$E$2:$G$1025,2,FALSE) -> SAMEA7723524 | P16: =VLOOKUP(O16,'anc gold to biosample'!$A$2:$B$1025,2,FALSE) -> Gb0315882 | Q16: =VLOOKUP(P16,'anc nmdc ncbi gold'!$A$2:$C$818,2,FALSE) -> nmdc:bsm-11-1j6kvc24 | R16: some nmdc biosample ids subject to change, update 'anc nmdc ncbi gold' before using for prod work
A17: EMP_Feces_berry_2_s005_a03_M_093 | B17: 698740 | D17: 94 | E17: 2856 | F17: 5 | G17: 43356.569 | H17: 43356.595 | I17: 37 | J17: Agilent_GC_MS_02 | K17: \\proto-4\Agilent_GC_MS_02\2018_3\EMP_Feces_berry_2_s005_a03_M_093\ | L17: =IF(LEFT(A17,10)="EMP_Feces_",MID(A17,11,FIND("a0",A17,1)-12),"None") -> berry_2_s005 | M17: =IF(NOT(L17="None"),VLOOKUP(L17,'GOLD Name splitout'!$A$1:$B$458,2,FALSE),"None") -> nmdc:bsm-11-1kc3zb19 | N17: =VLOOKUP(A17,DMSNameNCBIIDXNLExtract!$A$2:$B$318,2,FALSE) -> #N/A | O17: =VLOOKUP(L17,DMSNameNCBIIDXNLExtract!$E$2:$G$1025,2,FALSE) -> SAMEA7723851 | P17: =VLOOKUP(O17,'anc gold to biosample'!$A$2:$B$1025,2,FALSE) -> Gb0315768 | Q17: =VLOOKUP(P17,'anc nmdc ncbi gold'!$A$2:$C$818,2,FALSE) -> nmdc:bsm-11-1kc3zb19 | R17: some nmdc biosample ids subject to change, update 'anc nmdc ncbi gold' before using for prod work
A18: EMP_Feces_song_52_s004_a03_M_152 | B18: 698892 | D18: 94 | E18: 2856 | F18: 5 | G18: 43358.551 | H18: 43358.577 | I18: 37 | J18: Agilent_GC_MS_02 | K18: \\proto-4\Agilent_GC_MS_02\2018_3\EMP_Feces_song_52_s004_a03_M_152\ | L18: =IF(LEFT(A18,10)="EMP_Feces_",MID(A18,11,FIND("a0",A18,1)-12),"None") -> song_52_s004 | M18: =IF(NOT(L18="None"),VLOOKUP(L18,'GOLD Name splitout'!$A$1:$B$458,2,FALSE),"None") -> nmdc:bsm-11-1vny2356 | N18: =VLOOKUP(A18,DMSNameNCBIIDXNLExtract!$A$2:$B$318,2,FALSE) -> SAMEA7723521 | O18: =VLOOKUP(L18,DMSNameNCBIIDXNLExtract!$E$2:$G$1025,2,FALSE) -> SAMEA7723521 | P18: =VLOOKUP(O18,'anc gold to biosample'!$A$2:$B$1025,2,FALSE) -> Gb0315879 | Q18: =VLOOKUP(P18,'anc nmdc ncbi gold'!$A$2:$C$818,2,FALSE) -> nmdc:bsm-11-1vny2356 | R18: some nmdc biosample ids subject to change, update 'anc nmdc ncbi gold' before using for prod work
A19: EMP_Feces_song_51_s019_a03_M_147 | B19: 698883 | D19: 94 | E19: 2856 | F19: 5 | G19: 43358.403 | H19: 43358.429 | I19: 37 | J19: Agilent_GC_MS_02 | K19: \\proto-4\Agilent_GC_MS_02\2018_3\EMP_Feces_song_51_s019_a03_M_147\ | L19: =IF(LEFT(A19,10)="EMP_Feces_",MID(A19,11,FIND("a0",A19,1)-12),"None") -> song_51_s019 | M19: =IF(NOT(L19="None"),VLOOKUP(L19,'GOLD Name splitout'!$A$1:$B$458,2,FALSE),"None") -> nmdc:bsm-11-1yc28a60 | N19: =VLOOKUP(A19,DMSNameNCBIIDXNLExtract!$A$2:$B$318,2,FALSE) -> SAMEA7723519 | O19: =VLOOKUP(L19,DMSNameNCBIIDXNLExtract!$E$2:$G$1025,2,FALSE) -> SAMEA7723519 | P19: =VLOOKUP(O19,'anc gold to biosample'!$A$2:$B$1025,2,FALSE) -> Gb0315877 | Q19: =VLOOKUP(P19,'anc nmdc ncbi gold'!$A$2:$C$818,2,FALSE) -> nmdc:bsm-11-1yc28a60 | R19: some nmdc biosample ids subject to change, update 'anc nmdc ncbi gold' before using for prod work
A20: EMP_Feces_king_27_s004_a03_M_213 | B20: 699453 | C20: Skipped Quameter since instrument class Agilent_Ion_Trap | D20: 94 | E20: 2856 | F20: 5 | G20: 43362.522 | H20: 43362.548 | I20: 37 | J20: Agilent_GC_MS_02 | K20: \\proto-4\Agilent_GC_MS_02\2018_3\EMP_Feces_king_27_s004_a03_M_213\ | L20: =IF(LEFT(A20,10)="EMP_Feces_",MID(A20,11,FIND("a0",A20,1)-12),"None") -> king_27_s004 | M20: =IF(NOT(L20="None"),VLOOKUP(L20,'GOLD Name splitout'!$A$1:$B$458,2,FALSE),"None") -> #N/A | N20: =VLOOKUP(A20,DMSNameNCBIIDXNLExtract!$A$2:$B$318,2,FALSE) -> SAMEA7724102 | O20: =VLOOKUP(L20,DMSNameNCBIIDXNLExtract!$E$2:$G$1025,2,FALSE) -> SAMEA7724102 | P20: =VLOOKUP(O20,'anc gold to biosample'!$A$2:$B$1025,2,FALSE) -> Gb0240114 | Q20: =VLOOKUP(P20,'anc nmdc ncbi gold'!$A$2:$C$818,2,FALSE) -> nmdc:bsm-11-228q6569 | R20: some nmdc biosample ids subject to change, update 'anc nmdc ncbi gold' before using for prod work
A21: EMP_Feces_sandin_54_s009_a03_M_316 | B21: 700242 | D21: 94 | E21: 2856 | F21: 5 | G21: 43367.85 | H21: 43367.876 | I21: 37 | J21: Agilent_GC_MS_02 | K21: \\proto-4\Agilent_GC_MS_02\2018_3\EMP_Feces_sandin_54_s009_a03_M_316\ | L21: =IF(LEFT(A21,10)="EMP_Feces_",MID(A21,11,FIND("a0",A21,1)-12),"None") -> sandin_54_s009 | M21: =IF(NOT(L21="None"),VLOOKUP(L21,'GOLD Name splitout'!$A$1:$B$458,2,FALSE),"None") -> nmdc:bsm-11-24619e70 | N21: =VLOOKUP(A21,DMSNameNCBIIDXNLExtract!$A$2:$B$318,2,FALSE) -> #N/A | O21: =VLOOKUP(L21,DMSNameNCBIIDXNLExtract!$E$2:$G$1025,2,FALSE) -> SAMEA7723968 | P21: =VLOOKUP(O21,'anc gold to biosample'!$A$2:$B$1025,2,FALSE) -> Gb0315654 | Q21: =VLOOKUP(P21,'anc nmdc ncbi gold'!$A$2:$C$818,2,FALSE) -> nmdc:bsm-11-24619e70 | R21: some nmdc biosample ids subject to change, update 'anc nmdc ncbi gold' before using for prod work
A22: EMP_Feces_rohwer_84_s006_a03_M_271 | B22: 699696 | D22: 94 | E22: 2856 | F22: 5 | G22: 43364.474 | H22: 43364.5 | I22: 37 | J22: Agilent_GC_MS_02 | K22: \\proto-4\Agilent_GC_MS_02\2018_3\EMP_Feces_rohwer_84_s006_a03_M_271\ | L22: =IF(LEFT(A22,10)="EMP_Feces_",MID(A22,11,FIND("a0",A22,1)-12),"None") -> rohwer_84_s006 | M22: =IF(NOT(L22="None"),VLOOKUP(L22,'GOLD Name splitout'!$A$1:$B$458,2,FALSE),"None") -> #N/A | N22: =VLOOKUP(A22,DMSNameNCBIIDXNLExtract!$A$2:$B$318,2,FALSE) -> #N/A | O22: =VLOOKUP(L22,DMSNameNCBIIDXNLExtract!$E$2:$G$1025,2,FALSE) -> SAMEA7723949 | P22: =VLOOKUP(O22,'anc gold to biosample'!$A$2:$B$1025,2,FALSE) -> Gb0239932 | Q22: =VLOOKUP(P22,'anc nmdc ncbi gold'!$A$2:$C$818,2,FALSE) -> nmdc:bsm-11-29kct608 | R22: some nmdc biosample ids subject to change, update 'anc nmdc ncbi gold' before using for prod work
A23: EMP_Stgn_p_t15_100m_101_GC | B23: 701179 | C23: ; Auto-switched invalid dataset type from GC to default: GC-MS | D23: 94 | E23: 2856 | F23: 5 | G23: 43371.659 | H23: 43371.685 | I23: 37 | J23: Agilent_GC_MS_02 | K23: \\proto-4\Agilent_GC_MS_02\2018_3\EMP_Stgn_p_t15_100m_101_GC\ | L23: =IF(LEFT(A23,10)="EMP_Feces_",MID(A23,11,FIND("a0",A23,1)-12),"None") -> None | M23: =IF(NOT(L23="None"),VLOOKUP(L23,'GOLD Name splitout'!$A$1:$B$458,2,FALSE),"None") -> None | N23: =VLOOKUP(A23,DMSNameNCBIIDXNLExtract!$A$2:$B$318,2,FALSE) -> SAMEA7724320 | O23: =N23 -> SAMEA7724320 | P23: =VLOOKUP(O23,'anc gold to biosample'!$A$2:$B$1025,2,FALSE) -> Gb0240034 | Q23: =VLOOKUP(P23,'anc nmdc ncbi gold'!$A$2:$C$818,2,FALSE) -> nmdc:bsm-11-2ah5z651 | R23: some nmdc biosample ids subject to change, update 'anc nmdc ncbi gold' before using for prod work
A24: EMP_Feces_berry_2_s019_a03_M_008 | B24: 697936 | D24: 94 | E24: 2856 | F24: 5 | G24: 43350.89 | H24: 43350.916 | I24: 37 | J24: Agilent_GC_MS_02 | K24: \\proto-4\Agilent_GC_MS_02\2018_3\EMP_Feces_berry_2_s019_a03_M_008\ | L24: =IF(LEFT(A24,10)="EMP_Feces_",MID(A24,11,FIND("a0",A24,1)-12),"None") -> berry_2_s019 | M24: =IF(NOT(L24="None"),VLOOKUP(L24,'GOLD Name splitout'!$A$1:$B$458,2,FALSE),"None") -> nmdc:bsm-11-2c8r9c97 | N24: =VLOOKUP(A24,DMSNameNCBIIDXNLExtract!$A$2:$B$318,2,FALSE) -> SAMEA7723398 | O24: =VLOOKUP(L24,DMSNameNCBIIDXNLExtract!$E$2:$G$1025,2,FALSE) -> SAMEA7723398 | P24: =VLOOKUP(O24,'anc gold to biosample'!$A$2:$B$1025,2,FALSE) -> Gb0315751 | Q24: =VLOOKUP(P24,'anc nmdc ncbi gold'!$A$2:$C$818,2,FALSE) -> nmdc:bsm-11-2c8r9c97 | R24: some nmdc biosample ids subject to change, update 'anc nmdc ncbi gold' before using for prod work
A25: EMP_Feces_mayer_33_s001_a03_M_194 | B25: 699285 | D25: 94 | E25: 2856 | F25: 5 | G25: 43361.96 | H25: 43361.986 | I25: 37 | J25: Agilent_GC_MS_02 | K25: \\proto-4\Agilent_GC_MS_02\2018_3\EMP_Feces_mayer_33_s001_a03_M_194\ | L25: =IF(LEFT(A25,10)="EMP_Feces_",MID(A25,11,FIND("a0",A25,1)-12),"None") -> mayer_33_s001 | M25: =IF(NOT(L25="None"),VLOOKUP(L25,'GOLD Name splitout'!$A$1:$B$458,2,FALSE),"None") -> nmdc:bsm-11-2drasm02 | N25: =VLOOKUP(A25,DMSNameNCBIIDXNLExtract!$A$2:$B$318,2,FALSE) -> SAMEA7723611 | O25: =VLOOKUP(L25,DMSNameNCBIIDXNLExtract!$E$2:$G$1025,2,FALSE) -> SAMEA7723611 | P25: =VLOOKUP(O25,'anc gold to biosample'!$A$2:$B$1025,2,FALSE) -> Gb0315763 | Q25: =VLOOKUP(P25,'anc nmdc ncbi gold'!$A$2:$C$818,2,FALSE) -> nmdc:bsm-11-2drasm02 | R25: some nmdc biosample ids subject to change, update 'anc nmdc ncbi gold' before using for prod work
A26: EMP_Sdf_P2_4_079_GC | B26: 700765 | C26: ; Auto-switched invalid dataset type from GC to default: GC-MS | D26: 94 | E26: 2856 | F26: 5 | G26: 43371.008 | H26: 43371.034 | I26: 37 | J26: Agilent_GC_MS_02 | K26: \\proto-4\Agilent_GC_MS_02\2018_3\EMP_Sdf_P2_4_079_GC\ | L26: =IF(LEFT(A26,10)="EMP_Feces_",MID(A26,11,FIND("a0",A26,1)-12),"None") -> None | M26: =IF(NOT(L26="None"),VLOOKUP(L26,'GOLD Name splitout'!$A$1:$B$458,2,FALSE),"None") -> None | N26: =VLOOKUP(A26,DMSNameNCBIIDXNLExtract!$A$2:$B$318,2,FALSE) -> SAMEA7724292 | O26: =N26 -> SAMEA7724292 | P26: =VLOOKUP(O26,'anc gold to biosample'!$A$2:$B$1025,2,FALSE) -> Gb0240019 | Q26: =VLOOKUP(P26,'anc nmdc ncbi gold'!$A$2:$C$818,2,FALSE) -> nmdc:bsm-11-2hv7wn93 | R26: some nmdc biosample ids subject to change, update 'anc nmdc ncbi gold' before using for prod work
A27: EMP_Feces_mayer_33_s002_a03_M_195 | B27: 699288 | D27: 94 | E27: 2856 | F27: 5 | G27: 43361.99 | H27: 43362.016 | I27: 37 | J27: Agilent_GC_MS_02 | K27: \\proto-4\Agilent_GC_MS_02\2018_3\EMP_Feces_mayer_33_s002_a03_M_195\ | L27: =IF(LEFT(A27,10)="EMP_Feces_",MID(A27,11,FIND("a0",A27,1)-12),"None") -> mayer_33_s002 | M27: =IF(NOT(L27="None"),VLOOKUP(L27,'GOLD Name splitout'!$A$1:$B$458,2,FALSE),"None") -> nmdc:bsm-11-2rtk4045 | N27: =VLOOKUP(A27,DMSNameNCBIIDXNLExtract!$A$2:$B$318,2,FALSE) -> SAMEA7723437 | O27: =VLOOKUP(L27,DMSNameNCBIIDXNLExtract!$E$2:$G$1025,2,FALSE) -> SAMEA7723437 | P27: =VLOOKUP(O27,'anc gold to biosample'!$A$2:$B$1025,2,FALSE) -> Gb0315752 | Q27: =VLOOKUP(P27,'anc nmdc ncbi gold'!$A$2:$C$818,2,FALSE) -> nmdc:bsm-11-2rtk4045 | R27: some nmdc biosample ids subject to change, update 'anc nmdc ncbi gold' before using for prod work
A28: EMP_Cen16_12_086_GC | B28: 700786 | C28: ; Auto-switched invalid dataset type from GC to default: GC-MS | D28: 94 | E28: 2856 | F28: 5 | G28: 43371.215 | H28: 43371.241 | I28: 37 | J28: Agilent_GC_MS_02 | K28: \\proto-4\Agilent_GC_MS_02\2018_3\EMP_Cen16_12_086_GC\ | L28: =IF(LEFT(A28,10)="EMP_Feces_",MID(A28,11,FIND("a0",A28,1)-12),"None") -> None | M28: =IF(NOT(L28="None"),VLOOKUP(L28,'GOLD Name splitout'!$A$1:$B$458,2,FALSE),"None") -> None | N28: =VLOOKUP(A28,DMSNameNCBIIDXNLExtract!$A$2:$B$318,2,FALSE) -> SAMEA7724303 | O28: =N28 -> SAMEA7724303 | P28: =VLOOKUP(O28,'anc gold to biosample'!$A$2:$B$1025,2,FALSE) -> Gb0239924 | Q28: =VLOOKUP(P28,'anc nmdc ncbi gold'!$A$2:$C$818,2,FALSE) -> nmdc:bsm-11-30npyx54 | R28: some nmdc biosample ids subject to change, update 'anc nmdc ncbi gold' before using for prod work
A29: EMP_Feces_king_27_s013_a03_M_219 | B29: 699482 | D29: 94 | E29: 2856 | F29: 5 | G29: 43362.818 | H29: 43362.844 | I29: 37 | J29: Agilent_GC_MS_02 | K29: \\proto-4\Agilent_GC_MS_02\2018_3\EMP_Feces_king_27_s013_a03_M_219\ | L29: =IF(LEFT(A29,10)="EMP_Feces_",MID(A29,11,FIND("a0",A29,1)-12),"None") -> king_27_s013 | M29: =IF(NOT(L29="None"),VLOOKUP(L29,'GOLD Name splitout'!$A$1:$B$458,2,FALSE),"None") -> #N/A | N29: =VLOOKUP(A29,DMSNameNCBIIDXNLExtract!$A$2:$B$318,2,FALSE) -> SAMEA7723432 | O29: =VLOOKUP(L29,DMSNameNCBIIDXNLExtract!$E$2:$G$1025,2,FALSE) -> SAMEA7723432 | P29: =VLOOKUP(O29,'anc gold to biosample'!$A$2:$B$1025,2,FALSE) -> Gb0240123 | Q29: =VLOOKUP(P29,'anc nmdc ncbi gold'!$A$2:$C$818,2,FALSE) -> nmdc:bsm-11-3396fd37 | R29: some nmdc biosample ids subject to change, update 'anc nmdc ncbi gold' before using for prod work
A30: EMP_Myr_5_NRCS0096_036_GC | B30: 700444 | C30: ; Auto-switched invalid dataset type from GC to default: GC-MS | D30: 94 | E30: 2856 | F30: 5 | G30: 43369.474 | H30: 43369.5 | I30: 37 | J30: Agilent_GC_MS_02 | K30: \\proto-4\Agilent_GC_MS_02\2018_3\EMP_Myr_5_NRCS0096_036_GC\ | L30: =MID(A30,5,14) -> Myr_5_NRCS0096 | M30: =IF(NOT(L30="None"),VLOOKUP(L30,'GOLD Name splitout'!$A$1:$B$458,2,FALSE),"None") -> #N/A | N30: =VLOOKUP(A30,DMSNameNCBIIDXNLExtract!$A$2:$B$318,2,FALSE) -> SAMEA7724211 | O30: =N30 -> SAMEA7724211 | P30: =VLOOKUP(O30,'anc gold to biosample'!$A$2:$B$1025,2,FALSE) -> Gb0240101 | Q30: =VLOOKUP(P30,'anc nmdc ncbi gold'!$A$2:$C$818,2,FALSE) -> nmdc:bsm-11-39qcw250 | R30: some nmdc biosample ids subject to change, update 'anc nmdc ncbi gold' before using for prod work
A31: EMP_Feces_thomas_18_s024_a03_M_027 | B31: 697995 | D31: 94 | E31: 2856 | F31: 5 | G31: 43351.451 | H31: 43351.477 | I31: 37 | J31: Agilent_GC_MS_02 | K31: \\proto-4\Agilent_GC_MS_02\2018_3\EMP_Feces_thomas_18_s024_a03_M_027\ | L31: =IF(LEFT(A31,10)="EMP_Feces_",MID(A31,11,FIND("a0",A31,1)-12),"None") -> thomas_18_s024 | M31: =IF(NOT(L31="None"),VLOOKUP(L31,'GOLD Name splitout'!$A$1:$B$458,2,FALSE),"None") -> nmdc:bsm-11-3a8h4b10 | N31: =VLOOKUP(A31,DMSNameNCBIIDXNLExtract!$A$2:$B$318,2,FALSE) -> SAMEA7723703 | O31: =VLOOKUP(L31,DMSNameNCBIIDXNLExtract!$E$2:$G$1025,2,FALSE) -> SAMEA7723703 | P31: =VLOOKUP(O31,'anc gold to biosample'!$A$2:$B$1025,2,FALSE) -> Gb0315815 | Q31: =VLOOKUP(P31,'anc nmdc ncbi gold'!$A$2:$C$818,2,FALSE) -> nmdc:bsm-11-3a8h4b10 | R31: some nmdc biosample ids subject to change, update 'anc nmdc ncbi gold' before using for prod work
A32: EMP_McR3_6_002_GC | B32: 698234 | C32: ; Auto-switched invalid dataset type from GC to default: GC-MS | D32: 94 | E32: 2856 | F32: 5 | G32: 43353.668 | H32: 43353.694 | I32: 37 | J32: Agilent_GC_MS_02 | K32: \\proto-4\Agilent_GC_MS_02\2018_3\EMP_McR3_6_002_GC\ | L32: McR3_6 | M32: =IF(NOT(L32="None"),VLOOKUP(L32,'GOLD Name splitout'!$A$1:$B$458,2,FALSE),"None") -> nmdc:bsm-11-3b5xj746 | N32: =VLOOKUP(A32,DMSNameNCBIIDXNLExtract!$A$2:$B$318,2,FALSE) -> SAMEA7724112 | O32: =VLOOKUP(L32,DMSNameNCBIIDXNLExtract!$E$2:$G$1025,2,FALSE) -> SAMEA7724112 | P32: =VLOOKUP(O32,'anc gold to biosample'!$A$2:$B$1025,2,FALSE) -> Gb0239958 | Q32: =VLOOKUP(P32,'anc nmdc ncbi gold'!$A$2:$C$818,2,FALSE) -> nmdc:bsm-11-3b5xj746 | R32: some nmdc biosample ids subject to change, update 'anc nmdc ncbi gold' before using for prod work
A33: EMP_Feces_king_27_s007_a03_M_214 | B33: 699463 | D33: 94 | E33: 2856 | F33: 5 | G33: 43362.552 | H33: 43362.578 | I33: 37 | J33: Agilent_GC_MS_02 | K33: \\proto-4\Agilent_GC_MS_02\2018_3\EMP_Feces_king_27_s007_a03_M_214\ | L33: =IF(LEFT(A33,10)="EMP_Feces_",MID(A33,11,FIND("a0",A33,1)-12),"None") -> king_27_s007 | M33: =IF(NOT(L33="None"),VLOOKUP(L33,'GOLD Name splitout'!$A$1:$B$458,2,FALSE),"None") -> #N/A | N33: =VLOOKUP(A33,DMSNameNCBIIDXNLExtract!$A$2:$B$318,2,FALSE) -> SAMEA7723430 | O33: =VLOOKUP(L33,DMSNameNCBIIDXNLExtract!$E$2:$G$1025,2,FALSE) -> SAMEA7723430 | P33: =VLOOKUP(O33,'anc gold to biosample'!$A$2:$B$1025,2,FALSE) -> Gb0240117 | Q33: =VLOOKUP(P33,'anc nmdc ncbi gold'!$A$2:$C$818,2,FALSE) -> nmdc:bsm-11-3ekef286 | R33: some nmdc biosample ids subject to change, update 'anc nmdc ncbi gold' before using for prod work
A34: EMP_Stgn_al_T5_52m_096_GC | B34: 701162 | C34: ; Auto-switched invalid dataset type from GC to default: GC-MS | D34: 94 | E34: 2856 | F34: 5 | G34: 43371.511 | H34: 43371.537 | I34: 37 | J34: Agilent_GC_MS_02 | K34: \\proto-4\Agilent_GC_MS_02\2018_3\EMP_Stgn_al_T5_52m_096_GC\ | L34: =IF(LEFT(A34,10)="EMP_Feces_",MID(A34,11,FIND("a0",A34,1)-12),"None") -> None | M34: =IF(NOT(L34="None"),VLOOKUP(L34,'GOLD Name splitout'!$A$1:$B$458,2,FALSE),"None") -> None | N34: =VLOOKUP(A34,DMSNameNCBIIDXNLExtract!$A$2:$B$318,2,FALSE) -> SAMEA7724337 | O34: =N34 -> SAMEA7724337 | P34: =VLOOKUP(O34,'anc gold to biosample'!$A$2:$B$1025,2,FALSE) -> Gb0240041 | Q34: =VLOOKUP(P34,'anc nmdc ncbi gold'!$A$2:$C$818,2,FALSE) -> nmdc:bsm-11-3h3w1c57 | R34: some nmdc biosample ids subject to change, update 'anc nmdc ncbi gold' before using for prod work
A35: EMP_Feces_uren_82_s006_a03_M_313 | B35: 700235 | D35: 94 | E35: 2856 | F35: 5 | G35: 43367.761 | H35: 43367.787 | I35: 37 | J35: Agilent_GC_MS_02 | K35: \\proto-4\Agilent_GC_MS_02\2018_3\EMP_Feces_uren_82_s006_a03_M_313\ | L35: =IF(LEFT(A35,10)="EMP_Feces_",MID(A35,11,FIND("a0",A35,1)-12),"None") -> uren_82_s006 | M35: =IF(NOT(L35="None"),VLOOKUP(L35,'GOLD Name splitout'!$A$1:$B$458,2,FALSE),"None") -> nmdc:bsm-11-3sdqfq80 | N35: =VLOOKUP(A35,DMSNameNCBIIDXNLExtract!$A$2:$B$318,2,FALSE) -> #N/A | O35: =VLOOKUP(L35,DMSNameNCBIIDXNLExtract!$E$2:$G$1025,2,FALSE) -> SAMEA7724049 | P35: =VLOOKUP(O35,'anc gold to biosample'!$A$2:$B$1025,2,FALSE) -> Gb0315697 | Q35: =VLOOKUP(P35,'anc nmdc ncbi gold'!$A$2:$C$818,2,FALSE) -> nmdc:bsm-11-3sdqfq80 | R35: some nmdc biosample ids subject to change, update 'anc nmdc ncbi gold' before using for prod work
A36: EMP_Sdf_BP2_26_074_GC | B36: 700735 | C36: ; Auto-switched invalid dataset type from GC to default: GC-MS | D36: 94 | E36: 2856 | F36: 5 | G36: 43370.742 | H36: 43370.768 | I36: 37 | J36: Agilent_GC_MS_02 | K36: \\proto-4\Agilent_GC_MS_02\2018_3\EMP_Sdf_BP2_26_074_GC\ | L36: =IF(LEFT(A36,10)="EMP_Feces_",MID(A36,11,FIND("a0",A36,1)-12),"None") -> None | M36: =IF(NOT(L36="None"),VLOOKUP(L36,'GOLD Name splitout'!$A$1:$B$458,2,FALSE),"None") -> None | N36: =VLOOKUP(A36,DMSNameNCBIIDXNLExtract!$A$2:$B$318,2,FALSE) -> SAMEA7724284 | O36: =N36 -> SAMEA7724284 | P36: =VLOOKUP(O36,'anc gold to biosample'!$A$2:$B$1025,2,FALSE) -> Gb0239936 | Q36: =VLOOKUP(P36,'anc nmdc ncbi gold'!$A$2:$C$818,2,FALSE) -> nmdc:bsm-11-407zcq77 | R36: some nmdc biosample ids subject to change, update 'anc nmdc ncbi gold' before using for prod work
A37: EMP_Feces_king_27_s008_a03_M_215 | B37: 699464 | D37: 94 | E37: 2856 | F37: 5 | G37: 43362.582 | H37: 43362.608 | I37: 37 | J37: Agilent_GC_MS_02 | K37: \\proto-4\Agilent_GC_MS_02\2018_3\EMP_Feces_king_27_s008_a03_M_215\ | L37: =IF(LEFT(A37,10)="EMP_Feces_",MID(A37,11,FIND("a0",A37,1)-12),"None") -> king_27_s008 | M37: =IF(NOT(L37="None"),VLOOKUP(L37,'GOLD Name splitout'!$A$1:$B$458,2,FALSE),"None") -> #N/A | N37: =VLOOKUP(A37,DMSNameNCBIIDXNLExtract!$A$2:$B$318,2,FALSE) -> SAMEA7723431 | O37: =VLOOKUP(L37,DMSNameNCBIIDXNLExtract!$E$2:$G$1025,2,FALSE) -> SAMEA7723431 | P37: =VLOOKUP(O37,'anc gold to biosample'!$A$2:$B$1025,2,FALSE) -> Gb0240118 | Q37: =VLOOKUP(P37,'anc nmdc ncbi gold'!$A$2:$C$818,2,FALSE) -> nmdc:bsm-11-44hrnd69 | R37: some nmdc biosample ids subject to change, update 'anc nmdc ncbi gold' before using for prod work
A38: EMP_Feces_sandin_54_s008_a03_M_315 | B38: 700240 | D38: 94 | E38: 2856 | F38: 5 | G38: 43367.82 | H38: 43367.846 | I38: 37 | J38: Agilent_GC_MS_02 | K38: \\proto-4\Agilent_GC_MS_02\2018_3\EMP_Feces_sandin_54_s008_a03_M_315\ | L38: =IF(LEFT(A38,10)="EMP_Feces_",MID(A38,11,FIND("a0",A38,1)-12),"None") -> sandin_54_s008 | M38: =IF(NOT(L38="None"),VLOOKUP(L38,'GOLD Name splitout'!$A$1:$B$458,2,FALSE),"None") -> nmdc:bsm-11-47n1jc77 | N38: =VLOOKUP(A38,DMSNameNCBIIDXNLExtract!$A$2:$B$318,2,FALSE) -> SAMEA7723503 | O38: =VLOOKUP(L38,DMSNameNCBIIDXNLExtract!$E$2:$G$1025,2,FALSE) -> SAMEA7723503 | P38: =VLOOKUP(O38,'anc gold to biosample'!$A$2:$B$1025,2,FALSE) -> Gb0315648 | Q38: =VLOOKUP(P38,'anc nmdc ncbi gold'!$A$2:$C$818,2,FALSE) -> nmdc:bsm-11-47n1jc77 | R38: some nmdc biosample ids subject to change, update 'anc nmdc ncbi gold' before using for prod work
A39: EMP_Feces_berry_2_s004_a03_M_092 | B39: 698711 | D39: 94 | E39: 2856 | F39: 5 | G39: 43356.54 | H39: 43356.566 | I39: 37 | J39: Agilent_GC_MS_02 | K39: \\proto-4\Agilent_GC_MS_02\2018_3\EMP_Feces_berry_2_s004_a03_M_092\ | L39: =IF(LEFT(A39,10)="EMP_Feces_",MID(A39,11,FIND("a0",A39,1)-12),"None") -> berry_2_s004 | M39: =IF(NOT(L39="None"),VLOOKUP(L39,'GOLD Name splitout'!$A$1:$B$458,2,FALSE),"None") -> nmdc:bsm-11-499zaf45 | N39: =VLOOKUP(A39,DMSNameNCBIIDXNLExtract!$A$2:$B$318,2,FALSE) -> SAMEA7723392 | O39: =VLOOKUP(L39,DMSNameNCBIIDXNLExtract!$E$2:$G$1025,2,FALSE) -> SAMEA7723392 | P39: =VLOOKUP(O39,'anc gold to biosample'!$A$2:$B$1025,2,FALSE) -> Gb0315745 | Q39: =VLOOKUP(P39,'anc nmdc ncbi gold'!$A$2:$C$818,2,FALSE) -> nmdc:bsm-11-499zaf45 | R39: some nmdc biosample ids subject to change, update 'anc nmdc ncbi gold' before using for prod work
A40: EMP_Feces_song_53_s004_a03_M_167 | B40: 699179 | D40: 94 | E40: 2856 | F40: 5 | G40: 43361.045 | H40: 43361.071 | I40: 37 | J40: Agilent_GC_MS_02 | K40: \\proto-4\Agilent_GC_MS_02\2018_3\EMP_Feces_song_53_s004_a03_M_167\ | L40: =IF(LEFT(A40,10)="EMP_Feces_",MID(A40,11,FIND("a0",A40,1)-12),"None") -> song_53_s004 | M40: =IF(NOT(L40="None"),VLOOKUP(L40,'GOLD Name splitout'!$A$1:$B$458,2,FALSE),"None") -> nmdc:bsm-11-49rak140 | N40: =VLOOKUP(A40,DMSNameNCBIIDXNLExtract!$A$2:$B$318,2,FALSE) -> SAMEA7723531 | O40: =VLOOKUP(L40,DMSNameNCBIIDXNLExtract!$E$2:$G$1025,2,FALSE) -> SAMEA7723531 | P40: =VLOOKUP(O40,'anc gold to biosample'!$A$2:$B$1025,2,FALSE) -> Gb0315889 | Q40: =VLOOKUP(P40,'anc nmdc ncbi gold'!$A$2:$C$818,2,FALSE) -> nmdc:bsm-11-49rak140 | R40: some nmdc biosample ids subject to change, update 'anc nmdc ncbi gold' before using for prod work
...

Sheet DMSNameNCBIIDXNLExtract
A1: gcms_sample_name | B1: ncbi ID | E1: short name | F1: external_id | G1: title
A2: EMP_Cen01_14_085_GC | B2: SAMEA7724297 | E2: 6_Mock_Community4 | F2: SAMEA7724070 | G2: 13114.6.Mock.Community4
A3: EMP_Cen03_14_092_GC | B3: SAMEA7724298 | E3: 6_Mock_Community3 | F3: SAMEA7724069 | G3: 13114.6.Mock.Community3
A4: EMP_Cen06_14_087_GC | B4: SAMEA7724299 | E4: 6_Mock_Community2 | F4: SAMEA7724068 | G4: 13114.6.Mock.Community2
A5: EMP_Cen12_12_084_GC | B5: SAMEA7724300 | E5: 6_Mock_Community1 | F5: SAMEA7724067 | G5: 13114.6.Mock.Community1
A6: EMP_Cen14_12_089_GC | B6: SAMEA7724301 | E6: 7_Mock_Community5 | F6: SAMEA7724075 | G6: 13114.7.Mock.Community5
A7: EMP_Cen15_12_090_GC | B7: SAMEA7724302 | E7: 7_Mock_Community4 | F7: SAMEA7724074 | G7: 13114.7.Mock.Community4
A8: EMP_Cen16_12_086_GC | B8: SAMEA7724303 | E8: 7_Mock_Community3 | F8: SAMEA7724073 | G8: 13114.7.Mock.Community3
A9: EMP_Cen17_12_088_GC | B9: SAMEA7724304 | E9: 7_Mock_Community2 | F9: SAMEA7724072 | G9: 13114.7.Mock.Community2
A10: EMP_Cen19_12_093_GC | B10: SAMEA7724305 | E10: 7_Mock_Community1 | F10: SAMEA7724071 | G10: 13114.7.Mock.Community1
A11: EMP_Cen20_12_091_GC | B11: SAMEA7724306 | E11: angenent_65_s009 | F11: SAMEA7724101 | G11: 13114.angenent.65.s009
A12: EMP_Feces_angenent_65_s001_a03_M_185 | B12: SAMEA7723388 | E12: angenent_65_s008 | F12: SAMEA7724100 | G12: 13114.angenent.65.s008
... A62: EMP_Feces_king_27_s004_a03_M_213 | B62: SAMEA7724102 | E62: BLANK1_1A_ITS | F62: SAMEA7724387 | G62: 13114.BLANK1.1A.ITS
A63: EMP_Feces_king_27_s007_a03_M_214 | B63: SAMEA7723430 | E63: #VALUE! | F63: SAMEA7724357 | G63: 13114.BLANK1.1D
A64: EMP_Feces_king_27_s008_a03_M_215 | B64: SAMEA7723431 | E64: #VALUE! | F64: SAMEA7724356 | G64: 13114.BLANK1.1C
A65: EMP_Feces_king_27_s013_a03_M_219 | B65: SAMEA7723432 | E65: #VALUE! | F65: SAMEA7724355 | G65: 13114.BLANK1.1B
A66: EMP_Feces_king_27_s017_a03_M_221 | B66: SAMEA7723434 | E66: #VALUE! | F66: SAMEA7724354 | G66: 13114.BLANK1.1A
A67: EMP_Feces_king_27_s018_a03_M_222 | B67: SAMEA7723435 | E67: BLANK2_2D_18S | F67: SAMEA7724449 | G67: 13114.BLANK2.2D.18S
A68: EMP_Feces_king_27_s019_a03_M_223 | B68: SAMEA7724106 | E68: BLANK2_2C_18S | F68: SAMEA7724448 | G68: 13114.BLANK2.2C.18S
A69: EMP_Feces_mayer_33_s001_a03_M_194 | B69: SAMEA7723611 | E69: BLANK2_2A_18S | F69: SAMEA7724446 | G69: 13114.BLANK2.2A.18S
A70: EMP_Feces_mayer_33_s002_a03_M_195 | B70: SAMEA7723437 | E70: BLANK2_2B_18S | F70: SAMEA7724447 | G70: 13114.BLANK2.2B.18S
A71: EMP_Feces_mayer_33_s003_a03_M_196 | B71: SAMEA7723438 | E71: BLANK2_2D_ITS | F71: SAMEA7724394 | G71: 13114.BLANK2.2D.ITS
A72: EMP_Feces_mayer_33_s005_a03_M_077 | B72: SAMEA7723612 | E72: BLANK2_2C_ITS | F72: SAMEA7724393 | G72: 13114.BLANK2.2C.ITS
A73: EMP_Feces_mayer_33_s007_a03_M_079 | B73: SAMEA7723439 | E73: BLANK2_2B_ITS | F73: SAMEA7724392 | G73: 13114.BLANK2.2B.ITS
A74: EMP_Feces_mayer_34_s001_a03_M_080 | B74: SAMEA7723440 | E74: BLANK2_2A_ITS | F74: SAMEA7724391 | G74: 13114.BLANK2.2A.ITS
A75: EMP_Feces_mayer_34_s002_a03_M_081 | B75: SAMEA7723441 | E75: #VALUE! | F75: SAMEA7724361 | G75: 13114.BLANK2.2D
A76: EMP_Feces_mayer_34_s006_a03_M_085 | B76: SAMEA7723442 | E76: #VALUE! | F76: SAMEA7724360 | G76: 13114.BLANK2.2C
A77: EMP_Feces_mayer_34_s009_a03_M_088 | B77: SAMEA7723613 | E77: #VALUE! | F77: SAMEA7724359 | G77: 13114.BLANK2.2B
A78: EMP_Feces_metcalf_40_s002_a03_M_069 | B78: SAMEA7723614 | E78: #VALUE! | F78: SAMEA7724358 | G78: 13114.BLANK2.2A
A79: EMP_Feces_metcalf_40_s006_a03_M_071 | B79: SAMEA7723447 | E79: BLANK3_3C_18S | F79: SAMEA7724450 | G79: 13114.BLANK3.3C.18S
A80: EMP_Feces_metcalf_40_s007_a03_M_072 | B80: SAMEA7723615 | E80: BLANK3_3D_18S | F80: SAMEA7724451 | G80: 13114.BLANK3.3D.18S
A81: EMP_Feces_metcalf_40_s010_a03_M_073 | B81: SAMEA7723449 | E81: BLANK3_3D_ITS | F81: SAMEA7724397 | G81: 13114.BLANK3.3D.ITS
A82: EMP_Feces_metcalf_40_s011_a03_M_074 | B82: SAMEA7723450 | E82: BLANK3_3C_ITS | F82: SAMEA7724396 | G82: 13114.BLANK3.3C.ITS
A83: EMP_Feces_metcalf_40_s013_a03_M_075 | B83: SAMEA7723451 | E83: BLANK3_3A_ITS | F83: SAMEA7724395 | G83: 13114.BLANK3.3A.ITS
A84: EMP_Feces_metcalf_81_s001_a03_M_267 | B84: SAMEA7723452 | E84: #VALUE! | F84: SAMEA7724365 | G84: 13114.BLANK3.3D
A85: EMP_Feces_metcalf_81_s002_a03_M_268 | B85: SAMEA7723453 | E85: #VALUE! | F85: SAMEA7724364 | G85: 13114.BLANK3.3C
A86: EMP_Feces_metcalf_81_s003_a03_M_269 | B86: SAMEA7723454 | E86: #VALUE! | F86: SAMEA7724363 | G86: 13114.BLANK3.3B
A87: EMP_Feces_minich_76_s001_a03_M_261 | B87: SAMEA7723455 | E87: #VALUE! | F87: SAMEA7724362 | G87: 13114.BLANK3.3A
A88: EMP_Feces_minich_76_s002_a03_M_262 | B88: SAMEA7723456 | E88: BLANK4_3D_18S | F88: SAMEA7724455 | G88: 13114.BLANK4.3D.18S
A89: EMP_Feces_minich_76_s003_a03_M_263 | B89: SAMEA7723457 | E89: BLANK4_3B_18S | F89: SAMEA7724453 | G89: 13114.BLANK4.3B.18S
...

Sheet MarksXML
A1: XML line using linebreaks at <BioSample access="public" publication | B1: character for gcms_sample_name | C1: extract of gcms_sample_name | D1: gcms_sample_name | E1: character for external_id | F1: external_id | G1: character for title | H1: extract of title | I1: title | J1: 1st term | K1: 2nd term | L1: 3rd term | M1: short name
A2: <BioSample access="public" publication_date="2020-12-17T00:00:00.000" last_update="2021-08-23T00:27:25.000" submission_date="2020-12-19T08:06:09.393" id="17119099" accession="SAMEA7724070"> <Ids> <Id db="BioSample" is_primary="1">SAMEA7724070</Id> <Id db="SRA">ERS5471447</Id> </Ids> <Description> <Title>13114.6.Mock.Community4</Title> <Organism taxonomy_id="1235509" taxonomy_name="synthetic metagenome"> <OrganismName>synthetic metagenome</OrganismName> </Organism> <Comment> <Paragraph>mock community</Paragraph> </Comment> </Description> <Owner> <Name>EBI</Name> </Owner> <Models> <Model>Generic</Model> </Models> <Package display_name="Generic">Generic.1.0</Package> <Attributes> <Attribute attribute_name="ENA first public">2020-12-17</Attribute> <Attribute attribute_name="ENA last update">2020-12-16</Attribute> <Attribute attribute_name="ENA-CHECKLIST">ERC000011</Attribute> <Attribute attribute_name="External Id">SAMEA7724070</Attribute> <Attribute attribute_name="INSDC center alias">UCSDMI</Attribute> <Attribute attribute_name="INSDC center name">University of California San Diego Microbiome Initiative</Attribute> <Attribute attribute_name="INSDC first public">2020-12-17T04:08:06Z</Attribute> <Attribute attribute_name="INSDC last update">2020-12-16T01:23:51Z</Attribute> <Attribute attribute_name="INSDC status">public</Attribute> <Attribute attribute_name="Submitter Id">qiita_sid_13114:13114.6.Mock.Community4</Attribute> <Attribute attribute_name="elevation" harmonized_name="elev" display_name="elevation">193</Attribute> <Attribute attribute_name="emp500_principal_investigator">Knight</Attribute> <Attribute attribute_name="empo_2">Positive</Attribute> <Attribute attribute_name="empo_3">Mock community</Attribute> <Attribute attribute_name="env biome" harmonized_name="env_broad_scale" display_name="broad-scale environmental context">urban biome</Attribute> <Attribute attribute_name="env feature" harmonized_name="env_local_scale" display_name="local-scale environmental context">research facility</Attribute> <Attribute attribute_name="env package" harmonized_name="env_package" display_name="environmental package">misc environment</Attribute> <Attribute attribute_name="env_material" harmonized_name="env_medium" display_name="environmental medium">cell culture</Attribute> <Attribute attribute_name="geo loc name" harmonized_name="geo_loc_name" display_name="geographic location">USA:CA,San Diego</Attribute> <Attribute attribute_name="latitude">32.5</Attribute> <Attribute attribute_name="longitude">-117.25</Attribute> <Attribute attribute_name="sample name" harmonized_name="sample_name" display_name="sample name">qiita_sid_13114:13114.6.Mock.Community4</Attribute> <Attribute attribute_name="sample type" harmonized_name="sample_type" display_name="sample type">mock community</Attribute> <Attribute attribute_name="sampling method">bulk</Attribute> </Attributes> <Status status="live" when="2020-12-20T10:35:01.454"/> </BioSample> | B2: =FIND("gcms_sample_name",A2,1) -> #VALUE! | C2: =MID(A2,B2,68) -> #VALUE! | D2: =MID(C2,19,FIND("/Attribute",C2,1)-20) -> #VALUE! | E2: =FIND("External Id",A2,1) -> 997 | F2: =MID(A2,E2+13,12) -> SAMEA7724070 | G2: =FIND("<Title>",A2,1) -> 317 | H2: =MID(A2,G2,68) -> <Title>13114.6.Mock.Community4</Title> <Organism taxonomy_id="12 | I2: =MID(H2,8,FIND("</Title>",H2,1)-8) -> 13114.6.Mock.Community4 | J2: =MID(I2,7,FIND(".",I2,8)-7) -> 6 | K2: =MID(I2,FIND(".",I2,8)+1,FIND(".",I2,FIND(".",I2,8)+1)-FIND(".",I2,8)-1) -> Mock | L2: =MID(I2,FIND(".",I2,FIND(".",I2,8)+1)+1,LEN(I2)-FIND(".",I2,FIND(".",I2,8)+1)) -> Community4 | M2: =J2&"_"&K2&"_"&L2 -> 6_Mock_Community4
A3: <BioSample access="public" publication_date="2020-12-17T00:00:00.000" last_update="2021-08-23T00:27:25.000" submission_date="2020-12-19T08:06:09.350" id="17119098" accession="SAMEA7724069"> <Ids> <Id db="BioSample" is_primary="1">SAMEA7724069</Id> <Id db="SRA">ERS5471446</Id> </Ids> <Description> <Title>13114.6.Mock.Community3</Title> <Organism taxonomy_id="1235509" taxonomy_name="synthetic metagenome"> <OrganismName>synthetic metagenome</OrganismName> </Organism> <Comment> <Paragraph>mock community</Paragraph> </Comment> </Description> <Owner> <Name>EBI</Name> </Owner> <Models> <Model>Generic</Model> </Models> <Package display_name="Generic">Generic.1.0</Package> <Attributes> <Attribute attribute_name="ENA first public">2020-12-17</Attribute> <Attribute attribute_name="ENA last update">2020-12-16</Attribute> <Attribute attribute_name="ENA-CHECKLIST">ERC000011</Attribute> <Attribute attribute_name="External Id">SAMEA7724069</Attribute> <Attribute attribute_name="INSDC center alias">UCSDMI</Attribute> <Attribute attribute_name="INSDC center name">University of California San Diego Microbiome Initiative</Attribute> <Attribute attribute_name="INSDC first public">2020-12-17T04:08:06Z</Attribute> <Attribute attribute_name="INSDC last update">2020-12-16T01:23:51Z</Attribute> <Attribute attribute_name="INSDC status">public</Attribute> <Attribute attribute_name="Submitter Id">qiita_sid_13114:13114.6.Mock.Community3</Attribute> <Attribute attribute_name="elevation" harmonized_name="elev" display_name="elevation">193</Attribute> <Attribute attribute_name="emp500_principal_investigator">Knight</Attribute> <Attribute attribute_name="empo_2">Positive</Attribute> <Attribute attribute_name="empo_3">Mock community</Attribute> <Attribute attribute_name="env biome" harmonized_name="env_broad_scale" display_name="broad-scale environmental context">urban biome</Attribute> <Attribute attribute_name="env feature" harmonized_name="env_local_scale" display_name="local-scale environmental context">research facility</Attribute> <Attribute attribute_name="env package" harmonized_name="env_package" display_name="environmental package">misc environment</Attribute> <Attribute attribute_name="env_material" harmonized_name="env_medium" display_name="environmental medium">cell culture</Attribute> <Attribute attribute_name="geo loc name" harmonized_name="geo_loc_name" display_name="geographic location">USA:CA,San Diego</Attribute> <Attribute attribute_name="latitude">32.5</Attribute> <Attribute attribute_name="longitude">-117.25</Attribute> <Attribute attribute_name="sample name" harmonized_name="sample_name" display_name="sample name">qiita_sid_13114:13114.6.Mock.Community3</Attribute> <Attribute attribute_name="sample type" harmonized_name="sample_type" display_name="sample type">mock community</Attribute> <Attribute attribute_name="sampling method">bulk</Attribute> </Attributes> <Status status="live" when="2020-12-20T10:34:14.865"/> </BioSample> | B3: =FIND("gcms_sample_name",A3,1) -> #VALUE! | C3: =MID(A3,B3,68) -> #VALUE! | D3: =MID(C3,19,FIND("/Attribute",C3,1)-20) -> #VALUE! | E3: =FIND("External Id",A3,1) -> 997 | F3: =MID(A3,E3+13,12) -> SAMEA7724069 | G3: =FIND("<Title>",A3,1) -> 317 | H3: =MID(A3,G3,68) -> <Title>13114.6.Mock.Community3</Title> <Organism taxonomy_id="12 | I3: =MID(H3,8,FIND("</Title>",H3,1)-8) -> 13114.6.Mock.Community3 | J3: =MID(I3,7,FIND(".",I3,8)-7) -> 6 | K3: =MID(I3,FIND(".",I3,8)+1,FIND(".",I3,FIND(".",I3,8)+1)-FIND(".",I3,8)-1) -> Mock | L3: =MID(I3,FIND(".",I3,FIND(".",I3,8)+1)+1,LEN(I3)-FIND(".",I3,FIND(".",I3,8)+1)) -> Community3 | M3: =J3&"_"&K3&"_"&L3 -> 6_Mock_Community3
A4: <BioSample access="public" publication_date="2020-12-17T00:00:00.000" last_update="2021-08-23T00:27:30.000" submission_date="2020-12-19T08:06:09.316" id="17119097" accession="SAMEA7724068"> <Ids> <Id db="BioSample" is_primary="1">SAMEA7724068</Id> <Id db="SRA">ERS5471445</Id> </Ids> <Description> <Title>13114.6.Mock.Community2</Title> <Organism taxonomy_id="1235509" taxonomy_name="synthetic metagenome"> <OrganismName>synthetic metagenome</OrganismName> </Organism> <Comment> <Paragraph>mock community</Paragraph> </Comment> </Description> <Owner> <Name>EBI</Name> </Owner> <Models> <Model>Generic</Model> </Models> <Package display_name="Generic">Generic.1.0</Package> <Attributes> <Attribute attribute_name="ENA first public">2020-12-17</Attribute> <Attribute attribute_name="ENA last update">2020-12-16</Attribute> <Attribute attribute_name="ENA-CHECKLIST">ERC000011</Attribute> <Attribute attribute_name="External Id">SAMEA7724068</Attribute> <Attribute attribute_name="INSDC center alias">UCSDMI</Attribute> <Attribute attribute_name="INSDC center name">University of California San Diego Microbiome Initiative</Attribute> <Attribute attribute_name="INSDC first public">2020-12-17T04:08:06Z</Attribute> <Attribute attribute_name="INSDC last update">2020-12-16T01:23:51Z</Attribute> <Attribute attribute_name="INSDC status">public</Attribute> <Attribute attribute_name="Submitter Id">qiita_sid_13114:13114.6.Mock.Community2</Attribute> <Attribute attribute_name="elevation" harmonized_name="elev" display_name="elevation">193</Attribute> <Attribute attribute_name="emp500_principal_investigator">Knight</Attribute> <Attribute attribute_name="empo_2">Positive</Attribute> <Attribute attribute_name="empo_3">Mock community</Attribute> <Attribute attribute_name="env biome" harmonized_name="env_broad_scale" display_name="broad-scale environmental context">urban biome</Attribute> <Attribute attribute_name="env feature" harmonized_name="env_local_scale" display_name="local-scale environmental context">research facility</Attribute> <Attribute attribute_name="env package" harmonized_name="env_package" display_name="environmental package">misc environment</Attribute> <Attribute attribute_name="env_material" harmonized_name="env_medium" display_name="environmental medium">cell culture</Attribute> <Attribute attribute_name="geo loc name" harmonized_name="geo_loc_name" display_name="geographic location">USA:CA,San Diego</Attribute> <Attribute attribute_name="latitude">32.5</Attribute> <Attribute attribute_name="longitude">-117.25</Attribute> <Attribute attribute_name="sample name" harmonized_name="sample_name" display_name="sample name">qiita_sid_13114:13114.6.Mock.Community2</Attribute> <Attribute attribute_name="sample type" harmonized_name="sample_type" display_name="sample type">mock community</Attribute> <Attribute attribute_name="sampling method">bulk</Attribute> </Attributes> <Status status="live" when="2020-12-20T10:35:26.195"/> </BioSample> | B4: =FIND("gcms_sample_name",A4,1) -> #VALUE! | C4: =MID(A4,B4,68) -> #VALUE! | D4: =MID(C4,19,FIND("/Attribute",C4,1)-20) -> #VALUE! | E4: =FIND("External Id",A4,1) -> 997 | F4: =MID(A4,E4+13,12) -> SAMEA7724068 | G4: =FIND("<Title>",A4,1) -> 317 | H4: =MID(A4,G4,68) -> <Title>13114.6.Mock.Community2</Title> <Organism taxonomy_id="12 | I4: =MID(H4,8,FIND("</Title>",H4,1)-8) -> 13114.6.Mock.Community2 | J4: =MID(I4,7,FIND(".",I4,8)-7) -> 6 | K4: =MID(I4,FIND(".",I4,8)+1,FIND(".",I4,FIND(".",I4,8)+1)-FIND(".",I4,8)-1) -> Mock | L4: =MID(I4,FIND(".",I4,FIND(".",I4,8)+1)+1,LEN(I4)-FIND(".",I4,FIND(".",I4,8)+1)) -> Community2 | M4: =J4&"_"&K4&"_"&L4 -> 6_Mock_Community2
A5: <BioSample access="public" publication_date="2020-12-17T00:00:00.000" last_update="2021-08-23T00:27:25.000" submission_date="2020-12-19T08:06:09.270" id="17119096" accession="SAMEA7724067"> <Ids> <Id db="BioSample" is_primary="1">SAMEA7724067</Id> <Id db="SRA">ERS5471444</Id> </Ids> <Description> <Title>13114.6.Mock.Community1</Title> <Organism taxonomy_id="1235509" taxonomy_name="synthetic metagenome"> <OrganismName>synthetic metagenome</OrganismName> </Organism> <Comment> <Paragraph>mock community</Paragraph> </Comment> </Description> <Owner> <Name>EBI</Name> </Owner> <Models> <Model>Generic</Model> </Models> <Package display_name="Generic">Generic.1.0</Package> <Attributes> <Attribute attribute_name="ENA first public">2020-12-17</Attribute> <Attribute attribute_name="ENA last update">2020-12-16</Attribute> <Attribute attribute_name="ENA-CHECKLIST">ERC000011</Attribute> <Attribute attribute_name="External Id">SAMEA7724067</Attribute> <Attribute attribute_name="INSDC center alias">UCSDMI</Attribute> <Attribute attribute_name="INSDC center name">University of California San Diego Microbiome Initiative</Attribute> <Attribute attribute_name="INSDC first public">2020-12-17T04:08:06Z</Attribute> <Attribute attribute_name="INSDC last update">2020-12-16T01:23:51Z</Attribute> <Attribute attribute_name="INSDC status">public</Attribute> <Attribute attribute_name="Submitter Id">qiita_sid_13114:13114.6.Mock.Community1</Attribute> <Attribute attribute_name="elevation" harmonized_name="elev" display_name="elevation">193</Attribute> <Attribute attribute_name="emp500_principal_investigator">Knight</Attribute> <Attribute attribute_name="empo_2">Positive</Attribute> <Attribute attribute_name="empo_3">Mock community</Attribute> <Attribute attribute_name="env biome" harmonized_name="env_broad_scale" display_name="broad-scale environmental context">urban biome</Attribute> <Attribute attribute_name="env feature" harmonized_name="env_local_scale" display_name="local-scale environmental context">research facility</Attribute> <Attribute attribute_name="env package" harmonized_name="env_package" display_name="environmental package">misc environment</Attribute> <Attribute attribute_name="env_material" harmonized_name="env_medium" display_name="environmental medium">cell culture</Attribute> <Attribute attribute_name="geo loc name" harmonized_name="geo_loc_name" display_name="geographic location">USA:CA,San Diego</Attribute> <Attribute attribute_name="latitude">32.5</Attribute> <Attribute attribute_name="longitude">-117.25</Attribute> <Attribute attribute_name="sample name" harmonized_name="sample_name" display_name="sample name">qiita_sid_13114:13114.6.Mock.Community1</Attribute> <Attribute attribute_name="sample type" harmonized_name="sample_type" display_name="sample type">mock community</Attribute> <Attribute attribute_name="sampling method">bulk</Attribute> </Attributes> <Status status="live" when="2020-12-20T10:34:54.319"/> </BioSample> | B5: =FIND("gcms_sample_name",A5,1) -> #VALUE! | C5: =MID(A5,B5,68) -> #VALUE! | D5: =MID(C5,19,FIND("/Attribute",C5,1)-20) -> #VALUE! | E5: =FIND("External Id",A5,1) -> 997 | F5: =MID(A5,E5+13,12) -> SAMEA7724067 | G5: =FIND("<Title>",A5,1) -> 317 | H5: =MID(A5,G5,68) -> <Title>13114.6.Mock.Community1</Title> <Organism taxonomy_id="12 | I5: =MID(H5,8,FIND("</Title>",H5,1)-8) -> 13114.6.Mock.Community1 | J5: =MID(I5,7,FIND(".",I5,8)-7) -> 6 | K5: =MID(I5,FIND(".",I5,8)+1,FIND(".",I5,FIND(".",I5,8)+1)-FIND(".",I5,8)-1) -> Mock | L5: =MID(I5,FIND(".",I5,FIND(".",I5,8)+1)+1,LEN(I5)-FIND(".",I5,FIND(".",I5,8)+1)) -> Community1 | M5: =J5&"_"&K5&"_"&L5 -> 6_Mock_Community1
A6: <BioSample access="public" publication_date="2020-12-17T00:00:00.000" last_update="2021-08-23T00:27:24.000" submission_date="2020-12-19T08:06:09.630" id="17119104" accession="SAMEA7724075"> <Ids> <Id db="BioSample" is_primary="1">SAMEA7724075</Id> <Id db="SRA">ERS5471452</Id> </Ids> <Description> <Title>13114.7.Mock.Community5</Title> <Organism taxonomy_id="1235509" taxonomy_name="synthetic metagenome"> <OrganismName>synthetic metagenome</OrganismName> </Organism> <Comment> <Paragraph>mock community</Paragraph> </Comment> </Description> <Owner> <Name>EBI</Name> </Owner> <Models> <Model>Generic</Model> </Models> <Package display_name="Generic">Generic.1.0</Package> <Attributes> <Attribute attribute_name="ENA first public">2020-12-17</Attribute> <Attribute attribute_name="ENA last update">2020-12-16</Attribute> <Attribute attribute_name="ENA-CHECKLIST">ERC000011</Attribute> <Attribute attribute_name="External Id">SAMEA7724075</Attribute> <Attribute attribute_name="INSDC center alias">UCSDMI</Attribute> <Attribute attribute_name="INSDC center name">University of California San Diego Microbiome Initiative</Attribute> <Attribute attribute_name="INSDC first public">2020-12-17T04:08:06Z</Attribute> <Attribute attribute_name="INSDC last update">2020-12-16T01:23:51Z</Attribute> <Attribute attribute_name="INSDC status">public</Attribute> <Attribute attribute_name="Submitter Id">qiita_sid_13114:13114.7.Mock.Community5</Attribute> <Attribute attribute_name="elevation" harmonized_name="elev" display_name="elevation">193</Attribute> <Attribute attribute_name="emp500_principal_investigator">Knight</Attribute> <Attribute attribute_name="empo_2">Positive</Attribute> <Attribute attribute_name="empo_3">Mock community</Attribute> <Attribute attribute_name="env biome" harmonized_name="env_broad_scale" display_name="broad-scale environmental context">urban biome</Attribute> <Attribute attribute_name="env feature" harmonized_name="env_local_scale" display_name="local-scale environmental context">research facility</Attribute> <Attribute attribute_name="env package" harmonized_name="env_package" display_name="environmental package">misc environment</Attribute> <Attribute attribute_name="env_material" harmonized_name="env_medium" display_name="environmental medium">cell culture</Attribute> <Attribute attribute_name="geo loc name" harmonized_name="geo_loc_name" display_name="geographic location">USA:CA,San Diego</Attribute> <Attribute attribute_name="latitude">32.5</Attribute> <Attribute attribute_name="longitude">-117.25</Attribute> <Attribute attribute_name="sample name" harmonized_name="sample_name" display_name="sample name">qiita_sid_13114:13114.7.Mock.Community5</Attribute> <Attribute attribute_name="sample type" harmonized_name="sample_type" display_name="sample type">mock community</Attribute> <Attribute attribute_name="sampling method">bulk</Attribute> </Attributes> <Status status="live" when="2020-12-20T10:34:24.113"/> </BioSample> | B6: =FIND("gcms_sample_name",A6,1) -> #VALUE! | C6: =MID(A6,B6,68) -> #VALUE! | D6: =MID(C6,19,FIND("/Attribute",C6,1)-20) -> #VALUE! | E6: =FIND("External Id",A6,1) -> 997 | F6: =MID(A6,E6+13,12) -> SAMEA7724075 | G6: =FIND("<Title>",A6,1) -> 317 | H6: =MID(A6,G6,68) -> <Title>13114.7.Mock.Community5</Title> <Organism taxonomy_id="12 | I6: =MID(H6,8,FIND("</Title>",H6,1)-8) -> 13114.7.Mock.Community5 | J6: =MID(I6,7,FIND(".",I6,8)-7) -> 7 | K6: =MID(I6,FIND(".",I6,8)+1,FIND(".",I6,FIND(".",I6,8)+1)-FIND(".",I6,8)-1) -> Mock | L6: =MID(I6,FIND(".",I6,FIND(".",I6,8)+1)+1,LEN(I6)-FIND(".",I6,FIND(".",I6,8)+1)) -> Community5 | M6: =J6&"_"&K6&"_"&L6 -> 7_Mock_Community5
